

===   [ 收集测试用例 ]  === 


== cases\case1.py 



===   [ 执行测试用例 ]  === 

预备执行用例数量 : 1



  ========= 测试开始 : 20250108_170555 =========



>>> cases\case1.py

* 计算器测试  -  2025-01-08 17:05:55

  [ case execution steps ]

-- 第 1 步 -- 3+9=12 


-- 第 2 步 -- 12*5=60 


** 检查点 **  验证结果 ---->  !! 不通过!!

  FAIL    
Traceback:
  File "D:\自动化实战\Appium练习\autotest\cases\case1.py", line 14, in teststeps
    CHECK_POINT('验证结果',result==60)
  File "D:\environment\python\Lib\site-packages\hytest\common.py", line 76, in CHECK_POINT
    raise AssertionError()
AssertionError



  ========= 测试结束 : 20250108_170630 =========


  耗时    : 35.070 秒


  预备执行用例数量 : 1

  实际执行用例数量 : 1

  通过 : 0

  失败 : 1

  异常 : 0

  套件初始化失败 : 0

  套件清除  失败 : 0

  用例初始化失败 : 0

  用例清除  失败 : 0
